<?xml version="1.0" ?>
<!-- =================================================================================== -->
<!-- |    This document was autogenerated by xacro from eod.xacro                      | -->
<!-- |    EDITING THIS FILE BY HAND IS NOT RECOMMENDED                                 | -->
<!-- =================================================================================== -->
<robot name="eod" xmlns:xacro="http://www.ros.org/wiki/xacro">
  <!-- Wheels -->
  <!-- Defining the colors used in this robot -->
  <material name="Black">
    <color rgba="0.0 0.0 0.0 1.0"/>
  </material>
  <material name="Red">
    <color rgba="0.8 0.0 0.0 1.0"/>
  </material>
  <material name="White">
    <color rgba="1.0 1.0 1.0 1.0"/>
  </material>
  <material name="Blue">
    <color rgba="0.0 0.0 0.8 1.0"/>
  </material>
  <!-- PROPERTY LIST -->
  <!--All units in m-kg-s-radians unit system -->
  <!-- Main body radius and height -->
  <!-- Main Body Cylinder base   -->
  <!-- distanza tra i centri delle due ruote -->
  <!-- distanza tra l'altezza del centro delle ruote (raggio) e la superfice
  inferiore della base -->
  <!-- Tower dimensions   -->
  <!-- wheel radius and height -->
  <!-- caster wheel radius and height -->
  <!-- Kinect dimensions   -->
  <!-- presunta altezza del sistema di riferimento della kinect -->
  <!-- Wheels -->
  <!--property name="base_x_origin_to_wheel_origin" value="0.25" />
  <property name="base_y_origin_to_wheel_origin" value="0.3" />
  <property name="base_z_origin_to_wheel_origin" value="0.0" /-->
  <!-- BASE-FOOTPRINT -->
  <!-- base_footprint is a fictitious link(frame) that is on the ground right below base_link origin -->
  <link name="base_footprint">
    <visual>
      <origin rpy="0 0 0" xyz="0 0 0"/>
      <geometry>
        <box size="0.001 0.001 0.001"/>
      </geometry>
    </visual>
  </link>
  <joint name="base_footprint_joint" type="fixed">
    <origin rpy="0 0 0" xyz="0 0 0.033"/>
    <parent link="base_footprint"/>
    <child link="base_link"/>
  </joint>
  <!-- BASE-LINK -->
  <!--Actual body/chassis of the robot-->
  <link name="base_link">
    <visual>
      <origin rpy="0 0 0" xyz="-0.026 0 0.0285"/>
      <geometry>
        <box size="0.212 0.1 0.033 "/>
      </geometry>
      <material name="White"/>
    </visual>
  </link>
  <!-- TOWER-LINK -->
  <link name="tower_link">
    <visual>
      <origin rpy="0 0 0" xyz="0 0 0"/>
      <geometry>
        <box size=" 0.027 0.072 0.225 "/>
      </geometry>
      <material name="White"/>
    </visual>
  </link>
  <joint name="tower_joint" type="fixed">
    <parent link="base_link"/>
    <child link="tower_link"/>
    <origin rpy="0 0 0" xyz="-0.1185 0.0 0.1575"/>
  </joint>
  <!--Caster -->
  <link name="caster_link">
    <visual>
      <origin rpy="0 0 0" xyz="0 0 -0.012"/>
      <geometry>
        <sphere radius="0.0225"/>
      </geometry>
      <material name="Black"/>
    </visual>
  </link>
  <joint name="caster_joint" type="fixed">
    <parent link="base_link"/>
    <child link="caster_link"/>
    <origin rpy="0 0 0" xyz="-0.115 0.0 0"/>
  </joint>
  <!-- Wheel Definitions -->
  <!--fb : front, back ; lr: left, right -->
  <link name="right_wheel">
    <visual>
      <origin rpy="1.57079632679 0  0 " xyz="0 0 0"/>
      <geometry>
        <cylinder length="0.021" radius="0.033"/>
      </geometry>
      <material name="DarkGray"/>
    </visual>
  </link>
  <joint name="right_wheel_joint" type="continuous">
    <parent link="base_link"/>
    <child link="right_wheel"/>
    <origin rpy="0 0 0" xyz="0.0 0.06 0.0"/>
    <axis rpy="0 0 0" xyz="0 1 0"/>
    <limit effort="100" velocity="100"/>
    <joint_properties damping="0.0" friction="0.0"/>
  </joint>
  <!--fb : front, back ; lr: left, right -->
  <link name="left_wheel">
    <visual>
      <origin rpy="1.57079632679 0  0 " xyz="0 0 0"/>
      <geometry>
        <cylinder length="0.021" radius="0.033"/>
      </geometry>
      <material name="DarkGray"/>
    </visual>
  </link>
  <joint name="left_wheel_joint" type="continuous">
    <parent link="base_link"/>
    <child link="left_wheel"/>
    <origin rpy="0 0 0" xyz="0.0 -0.06 0.0"/>
    <axis rpy="0 0 0" xyz="0 1 0"/>
    <limit effort="100" velocity="100"/>
    <joint_properties damping="0.0" friction="0.0"/>
  </joint>
  <!-- SENSORS -->
  <!-- Kinect -->
  <link name="kinect_link">
    <visual>
      <origin rpy="0 0 0" xyz="0 0 -0.017"/>
      <geometry>
        <box size="0.07 0.28 0.07"/>
      </geometry>
      <material name="Blue"/>
    </visual>
  </link>
  <joint name="kinect_joint" type="fixed">
    <origin rpy="0 0 0" xyz="0 0 0.1655"/>
    <parent link="tower_link"/>
    <child link="kinect_link"/>
  </joint>
</robot>

