<?xml version="1.0" ?>
<!-- =================================================================================== -->
<!-- |    This document was autogenerated by xacro from eod.xacro                      | -->
<!-- |    EDITING THIS FILE BY HAND IS NOT RECOMMENDED                                 | -->
<!-- =================================================================================== -->
<robot name="eod" xmlns:xacro="http://ros.org/wiki/xacro">
  <!-- Wheels -->
  <!-- Microsoft Kinect / ASUS Xtion PRO Live for simulation -->
  <!-- 
    These properties must be observed by any machine
    that wants to be defined as a turtlebot. Refer
    to the REP for more details.
    
    http://www.ros.org/reps/rep-0119.html
   -->
  <!--
   ======================================================================
   - REP 119 : Rgb camera link relative to the Base link 
   ====================================================================== 
     Base link is currently defined as the rotational centre on the bottom
     of the base mould. For both create and kobuki this is actually exactly
     the same 3d world point. 
     
     This may cause an issue with a base with much different floor clearance.
     Should we be using base_footprint for this specification instead?
 
     Note: REP needs to be updated with the information below 
     (currently in development and awaiting feedback)
   -->
  <!--	<xacro:property name="cam_py" value="-0.0125" /> Y varies for different configurations. get sets in sensors_urdf -->
  <!-- Parameterised in part by the values in turtlebot_properties.urdf.xacro -->
  <!-- Defining the colors used in this robot -->
  <material name="Black">
    <color rgba="0.0 0.0 0.0 1.0"/>
  </material>
  <material name="Red">
    <color rgba="0.8 0.0 0.0 1.0"/>
  </material>
  <material name="White">
    <color rgba="1.0 1.0 1.0 1.0"/>
  </material>
  <material name="Blue">
    <color rgba="0.0 0.0 0.8 1.0"/>
  </material>
  <!-- PROPERTY LIST -->
  <!--All units in m-kg-s-radians unit system -->
  <!-- Main body radius and height -->
  <!-- Main Body Cylinder base   -->
  <!-- distanza tra i centri delle due ruote -->
  <!-- distanza tra l'altezza del centro delle ruote (raggio) e la superfice
  inferiore della base -->
  <!-- Tower dimensions   -->
  <!-- wheel radius and height -->
  <!-- caster wheel radius and height -->
  <!-- Kinect dimensions   -->
  <!--property name="kinect_height" value="0.07" /> 
  <property name="kinect_width" value="0.28" />
  <property name="kinect_length" value="0.07" /-->
  <!-- presunta altezza del sistema di riferimento della kinect -->
  <!--property name="kinect_focus_height" value="0.053" /-->
  <!-- Wheels -->
  <!--property name="base_x_origin_to_wheel_origin" value="0.25" />
  <property name="base_y_origin_to_wheel_origin" value="0.3" />
  <property name="base_z_origin_to_wheel_origin" value="0.0" /-->
  <!-- BASE-FOOTPRINT -->
  <!-- base_footprint is a fictitious link(frame) that is on the ground right below base_link origin -->
  <link name="base_footprint">
    <visual>
      <origin rpy="0 0 0" xyz="0 0 0"/>
      <geometry>
        <box size="0.001 0.001 0.001"/>
      </geometry>
    </visual>
  </link>
  <joint name="base_footprint_joint" type="fixed">
    <origin rpy="0 0 0" xyz="0 0 0.033"/>
    <parent link="base_footprint"/>
    <child link="base_link"/>
  </joint>
  <!-- BASE-LINK -->
  <!--Actual body/chassis of the robot-->
  <link name="base_link">
    <visual>
      <origin rpy="0 0 0" xyz="-0.026 0 0.0285"/>
      <geometry>
        <box size="0.212 0.1 0.033 "/>
      </geometry>
      <material name="White"/>
    </visual>
  </link>
  <!-- TOWER-LINK -->
  <link name="tower_link">
    <visual>
      <origin rpy="0 0 0" xyz="0 0 0"/>
      <geometry>
        <box size=" 0.027 0.072 0.225 "/>
      </geometry>
      <material name="White"/>
    </visual>
  </link>
  <joint name="tower_joint" type="fixed">
    <parent link="base_link"/>
    <child link="tower_link"/>
    <origin rpy="0 0 0" xyz="-0.1185 0.0 0.1575"/>
  </joint>
  <!--Caster -->
  <link name="caster_link">
    <visual>
      <origin rpy="0 0 0" xyz="0 0 -0.012"/>
      <geometry>
        <sphere radius="0.0215"/>
      </geometry>
      <material name="Black"/>
    </visual>
  </link>
  <joint name="caster_joint" type="fixed">
    <parent link="base_link"/>
    <child link="caster_link"/>
    <origin rpy="0 0 0" xyz="-0.115 0.0 0"/>
  </joint>
  <!-- Wheel Definitions -->
  <!--fb : front, back ; lr: left, right -->
  <link name="right_wheel">
    <visual>
      <origin rpy="1.57079632679 0  0 " xyz="0 0 0"/>
      <geometry>
        <cylinder length="0.021" radius="0.033"/>
      </geometry>
      <material name="DarkGray"/>
    </visual>
  </link>
  <joint name="right_wheel_joint" type="continuous">
    <parent link="base_link"/>
    <child link="right_wheel"/>
    <origin rpy="0 0 0" xyz="0.0 0.06 0.0"/>
    <axis rpy="0 0 0" xyz="0 1 0"/>
    <limit effort="100" velocity="100"/>
    <joint_properties damping="0.0" friction="0.0"/>
  </joint>
  <!--fb : front, back ; lr: left, right -->
  <link name="left_wheel">
    <visual>
      <origin rpy="1.57079632679 0  0 " xyz="0 0 0"/>
      <geometry>
        <cylinder length="0.021" radius="0.033"/>
      </geometry>
      <material name="DarkGray"/>
    </visual>
  </link>
  <joint name="left_wheel_joint" type="continuous">
    <parent link="base_link"/>
    <child link="left_wheel"/>
    <origin rpy="0 0 0" xyz="0.0 -0.06 0.0"/>
    <axis rpy="0 0 0" xyz="0 1 0"/>
    <limit effort="100" velocity="100"/>
    <joint_properties damping="0.0" friction="0.0"/>
  </joint>
  <!-- SENSORS -->
  <!-- Kinect -->
  <!--link name="kinect_link">
    <visual>
      <origin xyz="0 0 ${-(kinect_height-kinect_focus_height)}" rpy="0 0 0" />
      <geometry>
        <box size="${kinect_length} ${kinect_width} ${kinect_height}"/>
      </geometry>
      <material name="Blue" />
    </visual>
  </link>
  
  <joint name="kinect_joint" type="fixed">
    <origin xyz="0 0 ${tower_height/2 + kinect_focus_height}" rpy="0 0 0" />
    <parent link="tower_link"/>
    <child link="kinect_link" />
  </joint-->
  <joint name="camera_joint" type="fixed">
    <origin rpy="0 0 0" xyz="0 0 0.1475"/>
    <parent link="tower_link"/>
    <child link="camera_link"/>
  </joint>
  <joint name="camera_rgb_joint" type="fixed">
    <origin rpy="0 0 0" xyz="0.031 -0.0125 0.016"/>
    <parent link="camera_link"/>
    <child link="camera_rgb_frame"/>
  </joint>
  <link name="camera_rgb_frame"/>
  <joint name="camera_rgb_optical_joint" type="fixed">
    <origin rpy="-1.57079632679 0 -1.57079632679" xyz="0 0 0"/>
    <parent link="camera_rgb_frame"/>
    <child link="camera_rgb_optical_frame"/>
  </joint>
  <link name="camera_rgb_optical_frame"/>
  <link name="camera_link">
    <visual>
      <origin rpy="0 0 1.57079632679" xyz="0 0 0"/>
      <geometry>
        <mesh filename="package://turtlebot_description/meshes/sensors/kinect.dae"/>
      </geometry>
    </visual>
    <collision>
      <origin rpy="0 0 0" xyz="0.0 0.0 0.0"/>
      <geometry>
        <box size="0.07271 0.27794 0.073"/>
      </geometry>
    </collision>
    <inertial>
      <mass value="0.564"/>
      <origin xyz="0 0 0"/>
      <inertia ixx="0.003881243" ixy="0.0" ixz="0.0" iyy="0.000498940" iyz="0.0" izz="0.003879257"/>
    </inertial>
  </link>
</robot>

